Workbook

Sheet Timeline Feb'26

Sheet Overview
A1: ="Overall Company KPI Achievement "&TEXT(TODAY()-29,"MMM-YY") -> Overall Company KPI Achievement Mar-26
A2: Company Measurement
B3: Month | E3: Accumulate
B4: Total | C4: Achieved | D4: Unachieved | E4: Total | F4: Achieved | G4: Unachieved
A5: 1. Safety | B5: 3 | C5: 3 | D5: 0 | E5: 4 | F5: 3 | G5: 3
B6: 5 | C6: 4 | D6: 1 | E6: 5 | F6: 1 | G6: 4
A7: 2. Quality | B7: 7 | C7: =SUMIF(Summary_SDM!C7:C110,Overview!#REF!,Summary_SDM!Z7:Z109) -> 0 | D7: =SUMIF(Summary_SDM!D7:D110,Overview!#REF!,Summary_SDM!AA7:AA107) -> 0 | E7: 7 | F7: =SUMIF(Summary_SDM!F7:F110,Overview!#REF!,Summary_SDM!AC7:AC107) -> 0 | G7: =SUMIF(Summary_SDM!G7:G110,Overview!#REF!,Summary_SDM!AD7:AD107) -> 0
B8: 2 | C8: =SUMIF(Summary_SDM!C8:C111,Overview!#REF!,Summary_SDM!Z8:Z110) -> 0 | D8: =SUMIF(Summary_SDM!D8:D111,Overview!#REF!,Summary_SDM!AA8:AA108) -> 0 | E8: 2 | F8: =SUMIF(Summary_SDM!F8:F111,Overview!#REF!,Summary_SDM!AC8:AC108) -> 0 | G8: =SUMIF(Summary_SDM!G8:G111,Overview!#REF!,Summary_SDM!AD8:AD108) -> 0
A9: 3. Delivery | B9: 2 | C9: 2 | D9: =SUMIF(Summary_SDM!D9:D112,Overview!#REF!,Summary_SDM!AA9:AA109) -> 0 | E9: 2 | F9: 2 | G9: 0
B10: 2 | C10: 2 | D10: =SUMIF(Summary_SDM!D10:D113,Overview!#REF!,Summary_SDM!AA10:AA110) -> 0 | E10: 2 | F10: 2 | G10: 0
B11: 1 | C11: 1 | D11: =SUMIF(Summary_SDM!D11:D114,Overview!#REF!,Summary_SDM!AA11:AA111) -> 0 | E11: 1 | F11: 1 | G11: 0
A12: 4. Compliance | B12: 18 | E12: 6
A13: 5. HR | B13: - | C13: - | D13: - | E13: 5 | F13: 5 | G13: 0
A14: 6. Attractive | B14: 3 | C14: 2 | D14: 1 | E14: 3 | F14: 2 | G14: 1
A15: 7.Envi. | B15: 7 | C15: 6 | D15: 1 | E15: 8 | F15: 7 | G15: 1
A16: 8. Cost | B16: 7 | C16: 5 | D16: 2 | E16: 7 | F16: 6 | G16: 1
B17: =SUM(B5:B16) -> 57 | E17: =SUM(E5:E16) -> 52

Sheet Summary_SDM
B2: ="Overall Company KPI Achievement "&TEXT(O2,"MMM-YY") -> Overall Company KPI Achievement Feb-26 | O2: 46054
B3: Company Measurement | F3: Freq. | G3: Unit | H3: FY25 Target | I3: Target | J3: Result | K3: Judge | L3: Accu. Target | M3: Accu. Result | N3: Accu. Judge | O3: President award | P3: Explain Item ●：Need ○：No Need | S3: Key of problem | T3: Explain item/No. | V3: Overview result | Y3: Acc | Z3: Month
P4: Monthly | Q4: Accu. | R4: C/S
B5: 1. Safety | C5: worksite | D5: 1 | E5: 1-Grade accident | F5: 1/M | G5: Case | H5: 0 | I5: =SUMIFS(SDM_Data!$J$2:$J$1348,SDM_Data!$B$2:$B$1348,C5,SDM_Data!$D$2:$D$1348,E5,SDM_Data!$E$2:$E$1348,G5,SDM_Data!$I$2:$I$1348,$O$2) -> 0 | J5: =SUMIFS(SDM_Data!$K$2:$K$1348,SDM_Data!$B$2:$B$1348,C5,SDM_Data!$D$2:$D$1348,E5,SDM_Data!$E$2:$E$1348,G5,SDM_Data!$I$2:$I$1348,$O$2) -> 0 | K5: =IF(J5>I5,"X","O") -> O | L5: =SUMIFS(SDM_Data!$L$2:$L$1348,SDM_Data!$B$2:$B$1348,C5,SDM_Data!$D$2:$D$1348,E5,SDM_Data!$E$2:$E$1348,G5,SDM_Data!$I$2:$I$1348,$O$2) -> 0 | M5: =SUMIFS(SDM_Data!$M$2:$M$1348,SDM_Data!$B$2:$B$1348,C5,SDM_Data!$D$2:$D$1348,E5,SDM_Data!$E$2:$E$1348,G5,SDM_Data!$I$2:$I$1348,$O$2) -> 0 | N5: =IF(M5>L5,"X","O") -> O | O5: =IF(N5="O","15/15","0/15") -> 15/15 | P5: =IF(K5="X","l","") | Q5: =IF(N5="X","¡","") | S5: =Safety!B20 -> 1.Man : Authorized person Not follow regulation 2.System : Not have regulation to specific the Type of truck in each operation. | T5: SHE Monthly /19-Mar | V5: Monthly result | Y5: =IF(N5="O",1,0) -> 1 | Z5: =IF(K5="O",1,0) -> 1
C6: worksite | D6: =D5+1 -> 2 | E6: Reoccurrence | F6: 1/M | G6: Case | H6: 0 | I6: =SUMIFS(SDM_Data!$J$2:$J$1348,SDM_Data!$B$2:$B$1348,C6,SDM_Data!$D$2:$D$1348,E6,SDM_Data!$E$2:$E$1348,G6,SDM_Data!$I$2:$I$1348,$O$2) -> 0 | J6: =SUMIFS(SDM_Data!$K$2:$K$1348,SDM_Data!$B$2:$B$1348,C6,SDM_Data!$D$2:$D$1348,E6,SDM_Data!$E$2:$E$1348,G6,SDM_Data!$I$2:$I$1348,$O$2) -> 1 | K6: =IF(J6>I6,"X","O") -> X | L6: =SUMIFS(SDM_Data!$L$2:$L$1348,SDM_Data!$B$2:$B$1348,C6,SDM_Data!$D$2:$D$1348,E6,SDM_Data!$E$2:$E$1348,G6,SDM_Data!$I$2:$I$1348,$O$2) -> 0 | M6: =SUMIFS(SDM_Data!$M$2:$M$1348,SDM_Data!$B$2:$B$1348,C6,SDM_Data!$D$2:$D$1348,E6,SDM_Data!$E$2:$E$1348,G6,SDM_Data!$I$2:$I$1348,$O$2) -> 4 | N6: =IF(M6>L6,"X","O") -> X | O6: - | P6: =IF(K6="X","l","") -> l | Q6: =IF(N6="X","¡","") -> ¡ | T6: Report by | V6: Achieved | W6: Unachieved | X6: Total | Y6: =IF(N6="O",1,0) -> 0 | Z6: =IF(K6="O",1,0) -> 0
C7: Worksite | D7: 3 | E7: Near miss | F7: 1/M | G7: Case | H7: 4 | I7: =SUMIFS(SDM_Data!$J$2:$J$1348,SDM_Data!$B$2:$B$1348,C7,SDM_Data!$D$2:$D$1348,E7,SDM_Data!$E$2:$E$1348,G7,SDM_Data!$I$2:$I$1348,$O$2) -> 0 | J7: =SUMIFS(SDM_Data!$K$2:$K$1348,SDM_Data!$B$2:$B$1348,C7,SDM_Data!$D$2:$D$1348,E7,SDM_Data!$E$2:$E$1348,G7,SDM_Data!$I$2:$I$1348,$O$2) -> 0 | K7: =IF(J7>I7,"X","O") -> O | L7: =SUMIFS(SDM_Data!$L$2:$L$1348,SDM_Data!$B$2:$B$1348,C7,SDM_Data!$D$2:$D$1348,E7,SDM_Data!$E$2:$E$1348,G7,SDM_Data!$I$2:$I$1348,$O$2) -> 3 | M7: =SUMIFS(SDM_Data!$M$2:$M$1348,SDM_Data!$B$2:$B$1348,C7,SDM_Data!$D$2:$D$1348,E7,SDM_Data!$E$2:$E$1348,G7,SDM_Data!$I$2:$I$1348,$O$2) -> 3 | N7: =IF(M7>L7,"X","O") -> O | O7: - | P7: =IF(K7="X","l","") | Q7: =IF(N7="X","¡","") | R7: s | T7: K.Wannapa MGR | V7: =SUM(Z5:Z107) -> 36 | W7: =X7-V7 -> 18 | X7: =COUNT(Z5:Z107) -> 54 | Y7: =IF(N7="O",1,0) -> 1 | Z7: =IF(K7="O",1,0) -> 1
C8: worksite | D8: 4 | E8: 8-High risk audit (New) | F8: 1/Y | G8: Case | H8: 4 | I8: - | J8: - | K8: - | L8: 4 | M8: 5 | N8: =IF(M8>L8,"X","O") -> X | O8: - | P8: =IF(K8="X","l","") | Q8: =IF(N8="X","¡","") -> ¡ | T8: Result Oct'25 | Y8: =IF(N8="O",1,0) -> 0
C9: worksite | E9: 8-High risk audit (Reccourance) | F9: 1/Y | G9: Case | H9: 0 | I9: - | J9: - | K9: - | L9: =SUMIFS(SDM_Data!$L$2:$L$1348,SDM_Data!$B$2:$B$1348,C9,SDM_Data!$D$2:$D$1348,E9,SDM_Data!$E$2:$E$1348,G9,SDM_Data!$I$2:$I$1348,$O$2) -> 0 | M9: =SUMIFS(SDM_Data!$M$2:$M$1348,SDM_Data!$B$2:$B$1348,C9,SDM_Data!$D$2:$D$1348,E9,SDM_Data!$E$2:$E$1348,G9,SDM_Data!$I$2:$I$1348,$O$2) -> 0 | N9: =IF(M9>L9,"X","O") -> O | O9: - | P9: =IF(K9="X","l","") | Q9: =IF(N9="X","¡","") | V9: =V7/X7 -> 0.66666667
C10: Traffic | D10: 5 | E10: Fatal | F10: 1/M | G10: Case | H10: 0 | I10: =SUMIFS(SDM_Data!$J$2:$J$1348,SDM_Data!$B$2:$B$1348,C10,SDM_Data!$D$2:$D$1348,E10,SDM_Data!$E$2:$E$1348,G10,SDM_Data!$I$2:$I$1348,$O$2) -> 0 | J10: =SUMIFS(SDM_Data!$K$2:$K$1348,SDM_Data!$B$2:$B$1348,C10,SDM_Data!$D$2:$D$1348,E10,SDM_Data!$E$2:$E$1348,G10,SDM_Data!$I$2:$I$1348,$O$2) -> 0 | K10: =IF(J10>I10,"X","O") -> O | L10: =SUMIFS(SDM_Data!$L$2:$L$1348,SDM_Data!$B$2:$B$1348,C10,SDM_Data!$D$2:$D$1348,E10,SDM_Data!$E$2:$E$1348,G10,SDM_Data!$I$2:$I$1348,$O$2) -> 0 | M10: =SUMIFS(SDM_Data!$M$2:$M$1348,SDM_Data!$B$2:$B$1348,C10,SDM_Data!$D$2:$D$1348,E10,SDM_Data!$E$2:$E$1348,G10,SDM_Data!$I$2:$I$1348,$O$2) -> 1 | N10: =IF(M10>L10,"X","O") -> X | O10: - | P10: =IF(K10="X","l","") | Q10: =IF(N10="X","¡","") -> ¡ | R10: c | S10: - | T10: SHE Monthly /19-Mar | Y10: =IF(N10="O",1,0) -> 0 | Z10: =IF(K10="O",1,0) -> 1
C11: Traffic | D11: 6 | E11: Injury | F11: 1/M | G11: Case | H11: 0 | I11: =SUMIFS(SDM_Data!$J$2:$J$1348,SDM_Data!$B$2:$B$1348,C11,SDM_Data!$D$2:$D$1348,E11,SDM_Data!$E$2:$E$1348,G11,SDM_Data!$I$2:$I$1348,$O$2) -> 0 | J11: =SUMIFS(SDM_Data!$K$2:$K$1348,SDM_Data!$B$2:$B$1348,C11,SDM_Data!$D$2:$D$1348,E11,SDM_Data!$E$2:$E$1348,G11,SDM_Data!$I$2:$I$1348,$O$2) -> 0 | K11: =IF(J11>I11,"X","O") -> O | L11: =SUMIFS(SDM_Data!$L$2:$L$1348,SDM_Data!$B$2:$B$1348,C11,SDM_Data!$D$2:$D$1348,E11,SDM_Data!$E$2:$E$1348,G11,SDM_Data!$I$2:$I$1348,$O$2) -> 0 | M11: =SUMIFS(SDM_Data!$M$2:$M$1348,SDM_Data!$B$2:$B$1348,C11,SDM_Data!$D$2:$D$1348,E11,SDM_Data!$E$2:$E$1348,G11,SDM_Data!$I$2:$I$1348,$O$2) -> 2 | N11: =IF(M11>L11,"X","O") -> X | O11: - | P11: =IF(K11="X","¡","") | Q11: =IF(N11="X","¡","") -> ¡ | T11: Report by | Y11: =IF(N11="O",1,0) -> 0 | Z11: =IF(K11="O",1,0) -> 1
C12: Traffic | D12: 7 | E12: Illegal & dangerous driving | F12: 1/M | G12: Case | H12: 0 | I12: =SUMIFS(SDM_Data!$J$2:$J$1348,SDM_Data!$B$2:$B$1348,C12,SDM_Data!$D$2:$D$1348,E12,SDM_Data!$E$2:$E$1348,G12,SDM_Data!$I$2:$I$1348,$O$2) -> 0 | J12: =SUMIFS(SDM_Data!$K$2:$K$1348,SDM_Data!$B$2:$B$1348,C12,SDM_Data!$D$2:$D$1348,E12,SDM_Data!$E$2:$E$1348,G12,SDM_Data!$I$2:$I$1348,$O$2) -> 0 | K12: =IF(J12>I12,"X","O") -> O | L12: =SUMIFS(SDM_Data!$L$2:$L$1348,SDM_Data!$B$2:$B$1348,C12,SDM_Data!$D$2:$D$1348,E12,SDM_Data!$E$2:$E$1348,G12,SDM_Data!$I$2:$I$1348,$O$2) -> 0 | M12: =SUMIFS(SDM_Data!$M$2:$M$1348,SDM_Data!$B$2:$B$1348,C12,SDM_Data!$D$2:$D$1348,E12,SDM_Data!$E$2:$E$1348,G12,SDM_Data!$I$2:$I$1348,$O$2) -> 2 | N12: =IF(M12>L12,"X","O") -> X | O12: - | P12: =IF(K12="X","l","") | Q12: =IF(N12="X","¡","") -> ¡ | T12: K.Tharathip MGR | V12: Accumulate result | Y12: =IF(N12="O",1,0) -> 0 | Z12: =IF(K12="O",1,0) -> 1
C13: Traffic | D13: 8 | E13: Hit | F13: 1/M | G13: Case | H13: 0 | I13: =SUMIFS(SDM_Data!$J$2:$J$1348,SDM_Data!$B$2:$B$1348,C13,SDM_Data!$D$2:$D$1348,E13,SDM_Data!$E$2:$E$1348,G13,SDM_Data!$I$2:$I$1348,$O$2) -> 0 | J13: =SUMIFS(SDM_Data!$K$2:$K$1348,SDM_Data!$B$2:$B$1348,C13,SDM_Data!$D$2:$D$1348,E13,SDM_Data!$E$2:$E$1348,G13,SDM_Data!$I$2:$I$1348,$O$2) -> 0 | K13: =IF(J13>I13,"X","O") -> O | L13: =SUMIFS(SDM_Data!$L$2:$L$1348,SDM_Data!$B$2:$B$1348,C13,SDM_Data!$D$2:$D$1348,E13,SDM_Data!$E$2:$E$1348,G13,SDM_Data!$I$2:$I$1348,$O$2) -> 0 | M13: =SUMIFS(SDM_Data!$M$2:$M$1348,SDM_Data!$B$2:$B$1348,C13,SDM_Data!$D$2:$D$1348,E13,SDM_Data!$E$2:$E$1348,G13,SDM_Data!$I$2:$I$1348,$O$2) -> 1 | N13: =IF(M13>L13,"X","O") -> X | O13: =IF(N13="O","10/10","0/10") -> 0/10 | P13: =IF(K13="X","¡","") | Q13: =IF(N13="X","¡","") -> ¡ | V13: Achieved | W13: Unachieved | X13: Total | Y13: =IF(N13="O",1,0) -> 0 | Z13: =IF(K13="O",1,0) -> 1
C14: Traffic | D14: 9 | E14: Hit something | F14: 1/M | G14: Case | H14: 3 | I14: =SUMIFS(SDM_Data!$J$2:$J$1348,SDM_Data!$B$2:$B$1348,C14,SDM_Data!$D$2:$D$1348,E14,SDM_Data!$E$2:$E$1348,G14,SDM_Data!$I$2:$I$1348,$O$2) -> 0 | J14: =SUMIFS(SDM_Data!$K$2:$K$1348,SDM_Data!$B$2:$B$1348,C14,SDM_Data!$D$2:$D$1348,E14,SDM_Data!$E$2:$E$1348,G14,SDM_Data!$I$2:$I$1348,$O$2) -> 0 | K14: =IF(J14>I14,"X","O") -> O | L14: =SUMIFS(SDM_Data!$L$2:$L$1348,SDM_Data!$B$2:$B$1348,C14,SDM_Data!$D$2:$D$1348,E14,SDM_Data!$E$2:$E$1348,G14,SDM_Data!$I$2:$I$1348,$O$2) -> 3 | M14: =SUMIFS(SDM_Data!$M$2:$M$1348,SDM_Data!$B$2:$B$1348,C14,SDM_Data!$D$2:$D$1348,E14,SDM_Data!$E$2:$E$1348,G14,SDM_Data!$I$2:$I$1348,$O$2) -> 2 | N14: =IF(M14>L14,"X","O") -> O | O14: - | P14: =IF(K14="X","l","") | Q14: =IF(N14="X","¡","") | R14: c | V14: =SUM(Y5:Y107) -> 43 | W14: =X14-V14 -> 28 | X14: =COUNT(Y5:Y107) -> 71 | Y14: =IF(N14="O",1,0) -> 1 | Z14: =IF(K14="O",1,0) -> 1
B15: 2. Quality | C15: Claim | D15: =D14+1 -> 10 | E15: Critical claim | F15: 1/M | G15: Case | H15: 0 | I15: =SUMIFS(SDM_Data!$J$2:$J$1348,SDM_Data!$B$2:$B$1348,C15,SDM_Data!$D$2:$D$1348,E15,SDM_Data!$E$2:$E$1348,G15,SDM_Data!$I$2:$I$1348,$O$2) -> 0 | J15: =SUMIFS(SDM_Data!$K$2:$K$1348,SDM_Data!$B$2:$B$1348,C15,SDM_Data!$D$2:$D$1348,E15,SDM_Data!$E$2:$E$1348,G15,SDM_Data!$I$2:$I$1348,$O$2) -> 0 | K15: =IF(J15>I15,"X","O") -> O | L15: =SUMIFS(SDM_Data!$L$2:$L$1348,SDM_Data!$B$2:$B$1348,C15,SDM_Data!$D$2:$D$1348,E15,SDM_Data!$E$2:$E$1348,G15,SDM_Data!$I$2:$I$1348,$O$2) -> 0 | M15: =SUMIFS(SDM_Data!$M$2:$M$1348,SDM_Data!$B$2:$B$1348,C15,SDM_Data!$D$2:$D$1348,E15,SDM_Data!$E$2:$E$1348,G15,SDM_Data!$I$2:$I$1348,$O$2) -> 0 | N15: =IF(M15>L15,"X","O") -> O | O15: =IF(N15="O","15/15","0/15") -> 15/15 | P15: =IF(K15="X","l","") | Q15: =IF(N15="X","¡","") | Y15: =IF(N15="O",1,0) -> 1 | Z15: =IF(K15="O",1,0) -> 1
C16: Claim | D16: =D15+1 -> 11 | E16: 0-km claim (Official) | F16: 1/M | G16: Case | H16: 4 | I16: =SUMIFS(SDM_Data!$J$2:$J$1348,SDM_Data!$B$2:$B$1348,C16,SDM_Data!$D$2:$D$1348,E16,SDM_Data!$E$2:$E$1348,G16,SDM_Data!$I$2:$I$1348,$O$2) -> 0 | J16: =SUMIFS(SDM_Data!$K$2:$K$1348,SDM_Data!$B$2:$B$1348,C16,SDM_Data!$D$2:$D$1348,E16,SDM_Data!$E$2:$E$1348,G16,SDM_Data!$I$2:$I$1348,$O$2) -> 1 | K16: =IF(J16>I16,"X","O") -> X | L16: =SUMIFS(SDM_Data!$L$2:$L$1348,SDM_Data!$B$2:$B$1348,C16,SDM_Data!$D$2:$D$1348,E16,SDM_Data!$E$2:$E$1348,G16,SDM_Data!$I$2:$I$1348,$O$2) -> 4 | M16: =SUMIFS(SDM_Data!$M$2:$M$1348,SDM_Data!$B$2:$B$1348,C16,SDM_Data!$D$2:$D$1348,E16,SDM_Data!$E$2:$E$1348,G16,SDM_Data!$I$2:$I$1348,$O$2) -> 4 | N16: =IF(M16>L16,"X","O") -> O | O16: =IF(N16="O","10/10","0/10") -> 10/10 | P16: =IF(K16="X","l","") -> l | Q16: =IF(N16="X","¡","") | S16: 1. STM HP5S Engine cannot start (F/M Glue) Cause: Glue from jig ball air leak test at cylinder grinding process | T16: Quality monthly 11-Mar Report by Suphatcha MGR | V16: =V14/X14 -> 0.6056338 | Y16: =IF(N16="O",1,0) -> 1 | Z16: =IF(K16="O",1,0) -> 0
C17: Claim | D17: =D16+1 -> 12 | E17: 0-km claim (All DN response) | F17: 1/M | G17: Case | H17: 9 | I17: =SUMIFS(SDM_Data!$J$2:$J$1348,SDM_Data!$B$2:$B$1348,C17,SDM_Data!$D$2:$D$1348,E17,SDM_Data!$E$2:$E$1348,G17,SDM_Data!$I$2:$I$1348,$O$2) -> 1 | J17: =SUMIFS(SDM_Data!$K$2:$K$1348,SDM_Data!$B$2:$B$1348,C17,SDM_Data!$D$2:$D$1348,E17,SDM_Data!$E$2:$E$1348,G17,SDM_Data!$I$2:$I$1348,$O$2) -> 1 | K17: =IF(J17>I17,"X","O") -> O | L17: =SUMIFS(SDM_Data!$L$2:$L$1348,SDM_Data!$B$2:$B$1348,C17,SDM_Data!$D$2:$D$1348,E17,SDM_Data!$E$2:$E$1348,G17,SDM_Data!$I$2:$I$1348,$O$2) -> 9 | M17: =SUMIFS(SDM_Data!$M$2:$M$1348,SDM_Data!$B$2:$B$1348,C17,SDM_Data!$D$2:$D$1348,E17,SDM_Data!$E$2:$E$1348,G17,SDM_Data!$I$2:$I$1348,$O$2) -> 10 | N17: =IF(M17>L17,"X","O") -> X | O17: - | P17: =IF(K17="X","l","") | Q17: =IF(N17="X","¡","") -> ¡ | R17: c | Y17: =IF(N17="O",1,0) -> 0 | Z17: =IF(K17="O",1,0) -> 1
C18: Claim | D18: =D17+1 -> 13 | E18: Market claim | F18: 1/M | G18: Case | H18: - | I18: =SUMIFS(SDM_Data!$J$2:$J$1348,SDM_Data!$B$2:$B$1348,C18,SDM_Data!$D$2:$D$1348,E18,SDM_Data!$E$2:$E$1348,G18,SDM_Data!$I$2:$I$1348,$O$2) -> 0 | J18: =SUMIFS(SDM_Data!$K$2:$K$1348,SDM_Data!$B$2:$B$1348,C18,SDM_Data!$D$2:$D$1348,E18,SDM_Data!$E$2:$E$1348,G18,SDM_Data!$I$2:$I$1348,$O$2) -> 0 | K18: =IF(J18>I18,"X","O") -> O | L18: =SUMIFS(SDM_Data!$L$2:$L$1348,SDM_Data!$B$2:$B$1348,C18,SDM_Data!$D$2:$D$1348,E18,SDM_Data!$E$2:$E$1348,G18,SDM_Data!$I$2:$I$1348,$O$2) -> 0 | M18: =SUMIFS(SDM_Data!$M$2:$M$1348,SDM_Data!$B$2:$B$1348,C18,SDM_Data!$D$2:$D$1348,E18,SDM_Data!$E$2:$E$1348,G18,SDM_Data!$I$2:$I$1348,$O$2) -> 1 | N18: X | O18: - | P18: =IF(K18="X","l","") | Q18: =IF(N18="X","¡","") -> ¡ | R18: c | Y18: =IF(N18="O",1,0) -> 0 | Z18: =IF(K18="O",1,0) -> 1
C19: Claim | D19: =D18+1 -> 14 | E19: OGC claim | F19: 1/M | G19: Case | H19: 6 | I19: =SUMIFS(SDM_Data!$J$2:$J$1348,SDM_Data!$B$2:$B$1348,C19,SDM_Data!$D$2:$D$1348,E19,SDM_Data!$E$2:$E$1348,G19,SDM_Data!$I$2:$I$1348,$O$2) -> 0 | J19: =SUMIFS(SDM_Data!$K$2:$K$1348,SDM_Data!$B$2:$B$1348,C19,SDM_Data!$D$2:$D$1348,E19,SDM_Data!$E$2:$E$1348,G19,SDM_Data!$I$2:$I$1348,$O$2) -> 1 | K19: =IF(J19>I19,"X","O") -> X | L19: =SUMIFS(SDM_Data!$L$2:$L$1348,SDM_Data!$B$2:$B$1348,C19,SDM_Data!$D$2:$D$1348,E19,SDM_Data!$E$2:$E$1348,G19,SDM_Data!$I$2:$I$1348,$O$2) -> 5 | M19: =SUMIFS(SDM_Data!$M$2:$M$1348,SDM_Data!$B$2:$B$1348,C19,SDM_Data!$D$2:$D$1348,E19,SDM_Data!$E$2:$E$1348,G19,SDM_Data!$I$2:$I$1348,$O$2) -> 17 | N19: =IF(M19>L19,"X","O") -> X | O19: - | P19: =IF(K19="X","l","") -> l | Q19: =IF(N19="X","¡","") -> ¡ | R19: c | V19: President award result | Y19: =IF(N19="O",1,0) -> 0 | Z19: =IF(K19="O",1,0) -> 0
C20: Claim | D20: =D19+1 -> 15 | E20: Supplier NCR | F20: 1/M | G20: Case | H20: 6 | I20: =SUMIFS(SDM_Data!$J$2:$J$1348,SDM_Data!$B$2:$B$1348,C20,SDM_Data!$D$2:$D$1348,E20,SDM_Data!$E$2:$E$1348,G20,SDM_Data!$I$2:$I$1348,$O$2) -> 0 | J20: =SUMIFS(SDM_Data!$K$2:$K$1348,SDM_Data!$B$2:$B$1348,C20,SDM_Data!$D$2:$D$1348,E20,SDM_Data!$E$2:$E$1348,G20,SDM_Data!$I$2:$I$1348,$O$2) -> 2 | K20: =IF(J20>I20,"X","O") -> X | L20: =SUMIFS(SDM_Data!$L$2:$L$1348,SDM_Data!$B$2:$B$1348,C20,SDM_Data!$D$2:$D$1348,E20,SDM_Data!$E$2:$E$1348,G20,SDM_Data!$I$2:$I$1348,$O$2) -> 5 | M20: =SUMIFS(SDM_Data!$M$2:$M$1348,SDM_Data!$B$2:$B$1348,C20,SDM_Data!$D$2:$D$1348,E20,SDM_Data!$E$2:$E$1348,G20,SDM_Data!$I$2:$I$1348,$O$2) -> 16 | N20: =IF(M20>L20,"X","O") -> X | O20: - | P20: =IF(K20="X","l","") -> l | Q20: =IF(N20="X","¡","") -> ¡ | R20: c | S20: =Q_Claim!$K$39 -> 1. DMHU Plug rail Coating peeling Cause: Under invesitgate with supplier & DIAT 2. G3S Inlet connector missing ball Cause: Under investigation | V20: =SUM(RIGHT(O5,2)+RIGHT(O13,2)+RIGHT(O15,2)+RIGHT(O16,2)+RIGHT(O22,2)+RIGHT(O88,1)+RIGHT(O99,1)+RIGHT(O101,2)+RIGHT(O102,2))&"/100" -> 100/100 | Y20: =IF(N20="O",1,0) -> 0 | Z20: =IF(K20="O",1,0) -> 0
C21: Claim | D21: =D20+1 -> 16 | E21: Internal NCR | F21: 1/M | G21: Case | H21: 5 | I21: =SUMIFS(SDM_Data!$J$2:$J$1348,SDM_Data!$B$2:$B$1348,C21,SDM_Data!$D$2:$D$1348,E21,SDM_Data!$E$2:$E$1348,G21,SDM_Data!$I$2:$I$1348,$O$2) -> 1 | J21: =SUMIFS(SDM_Data!$K$2:$K$1348,SDM_Data!$B$2:$B$1348,C21,SDM_Data!$D$2:$D$1348,E21,SDM_Data!$E$2:$E$1348,G21,SDM_Data!$I$2:$I$1348,$O$2) -> 2 | K21: =IF(J21>I21,"X","O") -> X | L21: =SUMIFS(SDM_Data!$L$2:$L$1348,SDM_Data!$B$2:$B$1348,C21,SDM_Data!$D$2:$D$1348,E21,SDM_Data!$E$2:$E$1348,G21,SDM_Data!$I$2:$I$1348,$O$2) -> 5 | M21: =SUMIFS(SDM_Data!$M$2:$M$1348,SDM_Data!$B$2:$B$1348,C21,SDM_Data!$D$2:$D$1348,E21,SDM_Data!$E$2:$E$1348,G21,SDM_Data!$I$2:$I$1348,$O$2) -> 3 | N21: =IF(M21>L21,"X","O") -> O | O21: - | P21: =IF(K21="X","l","") -> l | Q21: =IF(N21="X","¡","") | S21: =Q_Claim!$F$39 -> 1. Rail Cap pipe fuel return Broken Cause: Under invesitgation 2. G3S Inlet connector missing ball Cause: Under investigation | T21: Quality monthly 11-Mar Report by Suphatcha MGR | Y21: =IF(N21="O",1,0) -> 1 | Z21: =IF(K21="O",1,0) -> 0
C22: Loss | D22: =D21+1 -> 17 | E22: Cost of spoilage | F22: 1/M | G22: % | H22: 0.0056 | I22: =SUMIFS(SDM_Data!$J$2:$J$1348,SDM_Data!$B$2:$B$1348,C22,SDM_Data!$D$2:$D$1348,E22,SDM_Data!$E$2:$E$1348,G22,SDM_Data!$I$2:$I$1348,$O$2) -> 0.0057988396 | J22: =SUMIFS(SDM_Data!$K$2:$K$1348,SDM_Data!$B$2:$B$1348,C22,SDM_Data!$D$2:$D$1348,E22,SDM_Data!$E$2:$E$1348,G22,SDM_Data!$I$2:$I$1348,$O$2) -> 0.0060065472 | K22: =IF(J22>I22,"X","O") -> X | L22: =SUMIFS(SDM_Data!$L$2:$L$1348,SDM_Data!$B$2:$B$1348,C22,SDM_Data!$D$2:$D$1348,E22,SDM_Data!$E$2:$E$1348,G22,SDM_Data!$I$2:$I$1348,$O$2) -> 0.00564 | M22: =SUMIFS(SDM_Data!$M$2:$M$1348,SDM_Data!$B$2:$B$1348,C22,SDM_Data!$D$2:$D$1348,E22,SDM_Data!$E$2:$E$1348,G22,SDM_Data!$I$2:$I$1348,$O$2) -> 0.0052878596 | N22: =IF(M22>L22,"X","O") -> O | O22: =IF(N22="O","10/10","0/10") -> 10/10 | P22: =IF(K22="X","l","") -> l | Q22: =IF(N22="X","¡","") | S22: GDP +1.24MB :P/L NG 1,146pcs [Plan 0.24%/Act 0.73%/Diff +0.49%] 1) Occure material DNTH cutting 601 run-out NG forecast end of Mar'26 (Forecast Mar'26 Over +1.2MB) 2) Occure in SDM process Relief seat grd. CPK 1.33 improvement M/C & Jig accuracy | Y22: =IF(N22="O",1,0) -> 1 | Z22: =IF(K22="O",1,0) -> 0
C23: Loss | E23: Cost of spoilage | F23: 1/M | G23: MB | H23: 162.9 | I23: =SUMIFS(SDM_Data!$J$2:$J$1348,SDM_Data!$B$2:$B$1348,C23,SDM_Data!$D$2:$D$1348,E23,SDM_Data!$E$2:$E$1348,G23,SDM_Data!$I$2:$I$1348,$O$2) -> 16.232374 | J23: =SUMIFS(SDM_Data!$K$2:$K$1348,SDM_Data!$B$2:$B$1348,C23,SDM_Data!$D$2:$D$1348,E23,SDM_Data!$E$2:$E$1348,G23,SDM_Data!$I$2:$I$1348,$O$2) -> 16.813799 | K23: =IF(J23>I23,"X","O") -> X | L23: =SUMIFS(SDM_Data!$L$2:$L$1348,SDM_Data!$B$2:$B$1348,C23,SDM_Data!$D$2:$D$1348,E23,SDM_Data!$E$2:$E$1348,G23,SDM_Data!$I$2:$I$1348,$O$2) -> 159.61695 | M23: =SUMIFS(SDM_Data!$M$2:$M$1348,SDM_Data!$B$2:$B$1348,C23,SDM_Data!$D$2:$D$1348,E23,SDM_Data!$E$2:$E$1348,G23,SDM_Data!$I$2:$I$1348,$O$2) -> 154.62741 | N23: =IF(M23>L23,"X","O") -> O | O23: - | Q23: =IF(N23="X","¡","")
C24: Loss | D24: =D22+1 -> 18 | E24: Quality loss | F24: 1/M | G24: MB | H24: 70.1 | I24: =SUMIFS(SDM_Data!$J$2:$J$1348,SDM_Data!$B$2:$B$1348,C24,SDM_Data!$D$2:$D$1348,E24,SDM_Data!$E$2:$E$1348,G24,SDM_Data!$I$2:$I$1348,$O$2) -> 4.48 | J24: =SUMIFS(SDM_Data!$K$2:$K$1348,SDM_Data!$B$2:$B$1348,C24,SDM_Data!$D$2:$D$1348,E24,SDM_Data!$E$2:$E$1348,G24,SDM_Data!$I$2:$I$1348,$O$2) -> 14.69 | K24: =IF(J24>I24,"X","O") -> X | L24: =SUMIFS(SDM_Data!$L$2:$L$1348,SDM_Data!$B$2:$B$1348,C24,SDM_Data!$D$2:$D$1348,E24,SDM_Data!$E$2:$E$1348,G24,SDM_Data!$I$2:$I$1348,$O$2) -> 65.97 | M24: =SUMIFS(SDM_Data!$M$2:$M$1348,SDM_Data!$B$2:$B$1348,C24,SDM_Data!$D$2:$D$1348,E24,SDM_Data!$E$2:$E$1348,G24,SDM_Data!$I$2:$I$1348,$O$2) -> 118.01 | N24: =IF(M24>L24,"X","O") -> X | O24: - | P24: =IF(K24="X","l","") -> l | Q24: =IF(N24="X","¡","") -> ¡ | R24: s | Y24: =IF(N24="O",1,0) -> 0 | Z24: =IF(K24="O",1,0) -> 0
B25: 3. Delivery | C25: Long BM >3 hr | D25: =D24+1 -> 19 | E25: Priority shipment line > 3hr | F25: 1/M | G25: Case | H25: 180 | I25: =SUMIFS(SDM_Data!$J$2:$J$1348,SDM_Data!$B$2:$B$1348,C25,SDM_Data!$D$2:$D$1348,E25,SDM_Data!$E$2:$E$1348,G25,SDM_Data!$I$2:$I$1348,$O$2) -> 26 | J25: =SUMIFS(SDM_Data!$K$2:$K$1348,SDM_Data!$B$2:$B$1348,C25,SDM_Data!$D$2:$D$1348,E25,SDM_Data!$E$2:$E$1348,G25,SDM_Data!$I$2:$I$1348,$O$2) -> 15 | K25: =IF(J25>I25,"X","O") -> O | L25: =SUMIFS(SDM_Data!$L$2:$L$1348,SDM_Data!$B$2:$B$1348,C25,SDM_Data!$D$2:$D$1348,E25,SDM_Data!$E$2:$E$1348,G25,SDM_Data!$I$2:$I$1348,$O$2) -> 296 | M25: =SUMIFS(SDM_Data!$M$2:$M$1348,SDM_Data!$B$2:$B$1348,C25,SDM_Data!$D$2:$D$1348,E25,SDM_Data!$E$2:$E$1348,G25,SDM_Data!$I$2:$I$1348,$O$2) -> 130 | N25: =IF(M25>L25,"X","O") -> O | O25: - | P25: =IF(K25="X","l","") | Q25: =IF(N25="X","¡","") | Y25: =IF(N25="O",1,0) -> 1 | Z25: =IF(K25="O",1,0) -> 1
C26: Unplanned holiday working | D26: 20 | E26: OT unplanned recovery from m/c BM | F26: 1/M | G26: Day | H26: 0 | I26: =SUMIFS(SDM_Data!$J$2:$J$1348,SDM_Data!$B$2:$B$1348,C26,SDM_Data!$D$2:$D$1348,E26,SDM_Data!$E$2:$E$1348,G26,SDM_Data!$I$2:$I$1348,$O$2) -> 0 | J26: =SUMIFS(SDM_Data!$K$2:$K$1348,SDM_Data!$B$2:$B$1348,C26,SDM_Data!$D$2:$D$1348,E26,SDM_Data!$E$2:$E$1348,G26,SDM_Data!$I$2:$I$1348,$O$2) -> 6 | K26: =IF(J26>I26,"X","O") -> X | L26: - | M26: - | N26: - | O26: - | P26: =IF(K26="X","l","") -> l | Q26: =IF(N26="X","¡","") | Y26: =IF(N27="O",1,0) -> 1 | Z26: =IF(K27="O",1,0) -> 1
C27: On plan delivery | D27: =D26+1 -> 21 | E27: - | F27: 1/M | G27: % | H27: 1 | I27: =SUMIFS(SDM_Data!$J$2:$J$1348,SDM_Data!$B$2:$B$1348,C27,SDM_Data!$D$2:$D$1348,E27,SDM_Data!$E$2:$E$1348,G27,SDM_Data!$I$2:$I$1348,$O$2) -> 1 | J27: =SUMIFS(SDM_Data!$K$2:$K$1348,SDM_Data!$B$2:$B$1348,C27,SDM_Data!$D$2:$D$1348,E27,SDM_Data!$E$2:$E$1348,G27,SDM_Data!$I$2:$I$1348,$O$2) -> 1 | K27: =IF(J27>I27,"X","O") -> O | L27: =SUMIFS(SDM_Data!$L$2:$L$1348,SDM_Data!$B$2:$B$1348,C27,SDM_Data!$D$2:$D$1348,E27,SDM_Data!$E$2:$E$1348,G27,SDM_Data!$I$2:$I$1348,$O$2) -> 1 | M27: =SUMIFS(SDM_Data!$M$2:$M$1348,SDM_Data!$B$2:$B$1348,C27,SDM_Data!$D$2:$D$1348,E27,SDM_Data!$E$2:$E$1348,G27,SDM_Data!$I$2:$I$1348,$O$2) -> 1 | N27: =IF(M27>L27,"X","O") -> O | O27: - | P27: =IF(K27="X","l","") | Q27: =IF(N27="X","¡","") | Y27: =IF(N28="O",1,0) -> 1 | Z27: =IF(K28="O",1,0) -> 1
C28: Nearmiss deliviery delay > 30 mins | D28: =D27+1 -> 22 | E28: - | F28: 1/M | G28: Case | H28: 0 | I28: =SUMIFS(SDM_Data!$J$2:$J$1348,SDM_Data!$B$2:$B$1348,C28,SDM_Data!$D$2:$D$1348,E28,SDM_Data!$E$2:$E$1348,G28,SDM_Data!$I$2:$I$1348,$O$2) -> 0 | J28: =SUMIFS(SDM_Data!$K$2:$K$1348,SDM_Data!$B$2:$B$1348,C28,SDM_Data!$D$2:$D$1348,E28,SDM_Data!$E$2:$E$1348,G28,SDM_Data!$I$2:$I$1348,$O$2) -> 0 | K28: =IF(J28>I28,"X","O") -> O | L28: =SUMIFS(SDM_Data!$L$2:$L$1348,SDM_Data!$B$2:$B$1348,C28,SDM_Data!$D$2:$D$1348,E28,SDM_Data!$E$2:$E$1348,G28,SDM_Data!$I$2:$I$1348,$O$2) -> 0 | M28: =SUMIFS(SDM_Data!$M$2:$M$1348,SDM_Data!$B$2:$B$1348,C28,SDM_Data!$D$2:$D$1348,E28,SDM_Data!$E$2:$E$1348,G28,SDM_Data!$I$2:$I$1348,$O$2) -> 0 | N28: =IF(M28>L28,"X","O") -> O | O28: - | P28: =IF(K28="X","l","") | Q28: =IF(N28="X","¡","") | Y28: =IF(N29="O",1,0) -> 1 | Z28: =IF(K29="O",1,0) -> 1
C29: Premium/Unplanned freight | D29: =D28+1 -> 23 | E29: - | F29: 1/M | G29: MB | H29: 7.65 | I29: =SUMIFS(SDM_Data!$J$2:$J$1348,SDM_Data!$B$2:$B$1348,C29,SDM_Data!$D$2:$D$1348,E29,SDM_Data!$E$2:$E$1348,G29,SDM_Data!$I$2:$I$1348,$O$2) -> 0.6375 | J29: =SUMIFS(SDM_Data!$K$2:$K$1348,SDM_Data!$B$2:$B$1348,C29,SDM_Data!$D$2:$D$1348,E29,SDM_Data!$E$2:$E$1348,G29,SDM_Data!$I$2:$I$1348,$O$2) -> 0.05 | K29: =IF(J29>I29,"X","O") -> O | L29: =SUMIFS(SDM_Data!$L$2:$L$1348,SDM_Data!$B$2:$B$1348,C29,SDM_Data!$D$2:$D$1348,E29,SDM_Data!$E$2:$E$1348,G29,SDM_Data!$I$2:$I$1348,$O$2) -> 7.015 | M29: =SUMIFS(SDM_Data!$M$2:$M$1348,SDM_Data!$B$2:$B$1348,C29,SDM_Data!$D$2:$D$1348,E29,SDM_Data!$E$2:$E$1348,G29,SDM_Data!$I$2:$I$1348,$O$2) -> 2.59 | N29: =IF(M29>L29,"X","O") -> O | O29: - | P29: =IF(K29="X","l","") | Q29: =IF(N29="X","¡","") | Y29: =IF(N30="O",1,0) -> 0 | Z29: =IF(K30="O",1,0) -> 1
B30: 4. Compliance | C30: Business compliance | D30: =D29+1 -> 24 | E30: Accident | F30: 1/M | G30: Case | H30: 0 | I30: =SUMIFS(SDM_Data!$J$2:$J$1348,SDM_Data!$B$2:$B$1348,C30,SDM_Data!$D$2:$D$1348,E30,SDM_Data!$E$2:$E$1348,G30,SDM_Data!$I$2:$I$1348,$O$2) -> 0 | J30: =SUMIFS(SDM_Data!$K$2:$K$1348,SDM_Data!$B$2:$B$1348,C30,SDM_Data!$D$2:$D$1348,E30,SDM_Data!$E$2:$E$1348,G30,SDM_Data!$I$2:$I$1348,$O$2) -> 0 | K30: =IF(J30>I30,"X","O") -> O | L30: =SUMIFS(SDM_Data!$L$2:$L$1348,SDM_Data!$B$2:$B$1348,C30,SDM_Data!$D$2:$D$1348,E30,SDM_Data!$E$2:$E$1348,G30,SDM_Data!$I$2:$I$1348,$O$2) -> 0 | M30: =SUMIFS(SDM_Data!$M$2:$M$1348,SDM_Data!$B$2:$B$1348,C30,SDM_Data!$D$2:$D$1348,E30,SDM_Data!$E$2:$E$1348,G30,SDM_Data!$I$2:$I$1348,$O$2) -> 5 | N30: =IF(M30>L30,"X","O") -> X | O30: - | P30: =IF(K30="X","l","") | Q30: =IF(N30="X","¡","") -> ¡ | Y30: =IF(N31="O",1,0) -> 0 | Z30: =IF(K31="O",1,0) -> 1
C31: Business compliance | D31: =D30+1 -> 25 | E31: Nearmiss | F31: 1/M | G31: Case | H31: 0 | I31: =SUMIFS(SDM_Data!$J$2:$J$1348,SDM_Data!$B$2:$B$1348,C31,SDM_Data!$D$2:$D$1348,E31,SDM_Data!$E$2:$E$1348,G31,SDM_Data!$I$2:$I$1348,$O$2) -> 0.75 | J31: =SUMIFS(SDM_Data!$K$2:$K$1348,SDM_Data!$B$2:$B$1348,C31,SDM_Data!$D$2:$D$1348,E31,SDM_Data!$E$2:$E$1348,G31,SDM_Data!$I$2:$I$1348,$O$2) -> 0 | K31: =IF(J31>I31,"X","O") -> O | L31: =SUMIFS(SDM_Data!$L$2:$L$1348,SDM_Data!$B$2:$B$1348,C31,SDM_Data!$D$2:$D$1348,E31,SDM_Data!$E$2:$E$1348,G31,SDM_Data!$I$2:$I$1348,$O$2) -> 0 | M31: =SUMIFS(SDM_Data!$M$2:$M$1348,SDM_Data!$B$2:$B$1348,C31,SDM_Data!$D$2:$D$1348,E31,SDM_Data!$E$2:$E$1348,G31,SDM_Data!$I$2:$I$1348,$O$2) -> 3 | N31: =IF(M31>L31,"X","O") -> X | O31: - | P31: =IF(K31="X","l","") | Q31: =IF(N31="X","¡","") -> ¡ | Y31: =IF(N32="O",1,0) -> 0 | Z31: =IF(K32="O",1,0) -> 1
C32: Business compliance | D32: =D31+1 -> 26 | E32: Incident | F32: 1/M | G32: Case | H32: 0 | I32: =SUMIFS(SDM_Data!$J$2:$J$1348,SDM_Data!$B$2:$B$1348,C32,SDM_Data!$D$2:$D$1348,E32,SDM_Data!$E$2:$E$1348,G32,SDM_Data!$I$2:$I$1348,$O$2) -> 0 | J32: =SUMIFS(SDM_Data!$K$2:$K$1348,SDM_Data!$B$2:$B$1348,C32,SDM_Data!$D$2:$D$1348,E32,SDM_Data!$E$2:$E$1348,G32,SDM_Data!$I$2:$I$1348,$O$2) -> 0 | K32: =IF(J32>I32,"X","O") -> O | L32: =SUMIFS(SDM_Data!$L$2:$L$1348,SDM_Data!$B$2:$B$1348,C32,SDM_Data!$D$2:$D$1348,E32,SDM_Data!$E$2:$E$1348,G32,SDM_Data!$I$2:$I$1348,$O$2) -> 0 | M32: =SUMIFS(SDM_Data!$M$2:$M$1348,SDM_Data!$B$2:$B$1348,C32,SDM_Data!$D$2:$D$1348,E32,SDM_Data!$E$2:$E$1348,G32,SDM_Data!$I$2:$I$1348,$O$2) -> 1 | N32: =IF(M32>L32,"X","O") -> X | O32: - | P32: =IF(K32="X","l","") | Q32: =IF(N32="X","¡","") -> ¡ | R32: c | S32: Result of Nov'25 | Y32: =IF(N33="O",1,0) -> 1 | Z32: =IF(K33="O",1,0) -> 1
C33: Business compliance | D33: =D32+1 -> 27 | E33: Urgent purchasing | F33: 1/M | G33: Case | H33: 281 | I33: =SUMIFS(SDM_Data!$J$2:$J$1348,SDM_Data!$B$2:$B$1348,C33,SDM_Data!$D$2:$D$1348,E33,SDM_Data!$E$2:$E$1348,G33,SDM_Data!$I$2:$I$1348,$O$2) -> 18 | J33: =SUMIFS(SDM_Data!$K$2:$K$1348,SDM_Data!$B$2:$B$1348,C33,SDM_Data!$D$2:$D$1348,E33,SDM_Data!$E$2:$E$1348,G33,SDM_Data!$I$2:$I$1348,$O$2) -> 6 | K33: =IF(J33>I33,"X","O") -> O | L33: =SUMIFS(SDM_Data!$L$2:$L$1348,SDM_Data!$B$2:$B$1348,C33,SDM_Data!$D$2:$D$1348,E33,SDM_Data!$E$2:$E$1348,G33,SDM_Data!$I$2:$I$1348,$O$2) -> 233 | M33: =SUMIFS(SDM_Data!$M$2:$M$1348,SDM_Data!$B$2:$B$1348,C33,SDM_Data!$D$2:$D$1348,E33,SDM_Data!$E$2:$E$1348,G33,SDM_Data!$I$2:$I$1348,$O$2) -> 197 | N33: =IF(M33>L33,"X","O") -> O | O33: - | P33: =IF(K33="X","l","") | Q33: =IF(N33="X","¡","")
C34: Business compliance | E34: Urgent purchasing | F34: 1/M | G34: MB | H34: 117 | I34: =SUMIFS(SDM_Data!$J$2:$J$1348,SDM_Data!$B$2:$B$1348,C34,SDM_Data!$D$2:$D$1348,E34,SDM_Data!$E$2:$E$1348,G34,SDM_Data!$I$2:$I$1348,$O$2) -> 3.95 | J34: =SUMIFS(SDM_Data!$K$2:$K$1348,SDM_Data!$B$2:$B$1348,C34,SDM_Data!$D$2:$D$1348,E34,SDM_Data!$E$2:$E$1348,G34,SDM_Data!$I$2:$I$1348,$O$2) -> 1.327 | K34: =IF(J34>I34,"X","O") -> O | L34: =SUMIFS(SDM_Data!$L$2:$L$1348,SDM_Data!$B$2:$B$1348,C34,SDM_Data!$D$2:$D$1348,E34,SDM_Data!$E$2:$E$1348,G34,SDM_Data!$I$2:$I$1348,$O$2) -> 92.109 | M34: =SUMIFS(SDM_Data!$M$2:$M$1348,SDM_Data!$B$2:$B$1348,C34,SDM_Data!$D$2:$D$1348,E34,SDM_Data!$E$2:$E$1348,G34,SDM_Data!$I$2:$I$1348,$O$2) -> 58.618 | N34: =IF(M34>L34,"X","O") -> O | O34: - | P34: =IF(K34="X","l","") | Q34: =IF(N34="X","¡","") | Y34: =IF(N35="O",1,0) -> 1 | Z34: =IF(K35="O",1,0) -> 0
C35: Business compliance | D35: =D33+1 -> 28 | E35: Urgent purchasing clear within3 Month | F35: 1/M | G35: Case | H35: 0 | I35: - | J35: - | K35: - | L35: =SUMIFS(SDM_Data!$L$2:$L$1348,SDM_Data!$B$2:$B$1348,C35,SDM_Data!$D$2:$D$1348,E35,SDM_Data!$E$2:$E$1348,G35,SDM_Data!$I$2:$I$1348,$O$2) -> 0 | M35: =SUMIFS(SDM_Data!$M$2:$M$1348,SDM_Data!$B$2:$B$1348,C35,SDM_Data!$D$2:$D$1348,E35,SDM_Data!$E$2:$E$1348,G35,SDM_Data!$I$2:$I$1348,$O$2) -> 0 | N35: =IF(M35>L35,"X","O") -> O | O35: - | P35: =IF(K35="X","l","") | Q35: =IF(N35="X","l","")
C36: Business compliance | E36: Urgent purchasing clear within3 Month | F36: 1/M | G36: MB | H36: 0 | I36: - | J36: - | K36: - | L36: =SUMIFS(SDM_Data!$L$2:$L$1348,SDM_Data!$B$2:$B$1348,C36,SDM_Data!$D$2:$D$1348,E36,SDM_Data!$E$2:$E$1348,G36,SDM_Data!$I$2:$I$1348,$O$2) -> 0 | M36: =SUMIFS(SDM_Data!$M$2:$M$1348,SDM_Data!$B$2:$B$1348,C36,SDM_Data!$D$2:$D$1348,E36,SDM_Data!$E$2:$E$1348,G36,SDM_Data!$I$2:$I$1348,$O$2) -> 0 | N36: =IF(M36>L36,"X","O") -> O | O36: - | P36: =IF(K36="X","l","") | Q36: =IF(N36="X","¡","") | Y36: =IF(N37="O",1,0) -> 1 | Z36: =IF(K37="O",1,0) -> 1
C37: Business compliance | D37: =D35+1 -> 29 | E37: Special purchasing | F37: 1/M | G37: Case | H37: 194 | I37: =SUMIFS(SDM_Data!$J$2:$J$1348,SDM_Data!$B$2:$B$1348,C37,SDM_Data!$D$2:$D$1348,E37,SDM_Data!$E$2:$E$1348,G37,SDM_Data!$I$2:$I$1348,$O$2) -> 8 | J37: =SUMIFS(SDM_Data!$K$2:$K$1348,SDM_Data!$B$2:$B$1348,C37,SDM_Data!$D$2:$D$1348,E37,SDM_Data!$E$2:$E$1348,G37,SDM_Data!$I$2:$I$1348,$O$2) -> 8 | K37: =IF(J37>I37,"X","O") -> O | L37: =SUMIFS(SDM_Data!$L$2:$L$1348,SDM_Data!$B$2:$B$1348,C37,SDM_Data!$D$2:$D$1348,E37,SDM_Data!$E$2:$E$1348,G37,SDM_Data!$I$2:$I$1348,$O$2) -> 172 | M37: =SUMIFS(SDM_Data!$M$2:$M$1348,SDM_Data!$B$2:$B$1348,C37,SDM_Data!$D$2:$D$1348,E37,SDM_Data!$E$2:$E$1348,G37,SDM_Data!$I$2:$I$1348,$O$2) -> 72 | N37: =IF(M37>L37,"X","O") -> O | O37: - | P37: =IF(K37="X","l","") | Q37: =IF(N37="X","¡","")
C38: Business compliance | E38: Special purchasing | F38: 1/M | G38: MB | H38: 313.1 | I38: =SUMIFS(SDM_Data!$J$2:$J$1348,SDM_Data!$B$2:$B$1348,C38,SDM_Data!$D$2:$D$1348,E38,SDM_Data!$E$2:$E$1348,G38,SDM_Data!$I$2:$I$1348,$O$2) -> 8.274 | J38: =SUMIFS(SDM_Data!$K$2:$K$1348,SDM_Data!$B$2:$B$1348,C38,SDM_Data!$D$2:$D$1348,E38,SDM_Data!$E$2:$E$1348,G38,SDM_Data!$I$2:$I$1348,$O$2) -> 7.262 | K38: =IF(J38>I38,"X","O") -> O | L38: =SUMIFS(SDM_Data!$L$2:$L$1348,SDM_Data!$B$2:$B$1348,C38,SDM_Data!$D$2:$D$1348,E38,SDM_Data!$E$2:$E$1348,G38,SDM_Data!$I$2:$I$1348,$O$2) -> 281.261 | M38: =SUMIFS(SDM_Data!$M$2:$M$1348,SDM_Data!$B$2:$B$1348,C38,SDM_Data!$D$2:$D$1348,E38,SDM_Data!$E$2:$E$1348,G38,SDM_Data!$I$2:$I$1348,$O$2) -> 69.426 | N38: =IF(M38>L38,"X","O") -> O | O38: - | P38: =IF(K38="X","l","") | Q38: =IF(N38="X","¡","") | Y38: =IF(N39="O",1,0) -> 1 | Z38: =IF(K39="O",1,0) -> 1
C39: Information security | D39: =D37+1 -> 30 | E39: Critical/Incident | F39: 1/M | G39: Case | H39: 0 | I39: =SUMIFS(SDM_Data!$J$2:$J$1348,SDM_Data!$B$2:$B$1348,C39,SDM_Data!$D$2:$D$1348,E39,SDM_Data!$E$2:$E$1348,G39,SDM_Data!$I$2:$I$1348,$O$2) -> 0 | J39: =SUMIFS(SDM_Data!$K$2:$K$1348,SDM_Data!$B$2:$B$1348,C39,SDM_Data!$D$2:$D$1348,E39,SDM_Data!$E$2:$E$1348,G39,SDM_Data!$I$2:$I$1348,$O$2) -> 0 | K39: =IF(J39>I39,"X","O") -> O | L39: =SUMIFS(SDM_Data!$L$2:$L$1348,SDM_Data!$B$2:$B$1348,C39,SDM_Data!$D$2:$D$1348,E39,SDM_Data!$E$2:$E$1348,G39,SDM_Data!$I$2:$I$1348,$O$2) -> 0 | M39: =SUMIFS(SDM_Data!$M$2:$M$1348,SDM_Data!$B$2:$B$1348,C39,SDM_Data!$D$2:$D$1348,E39,SDM_Data!$E$2:$E$1348,G39,SDM_Data!$I$2:$I$1348,$O$2) -> 0 | N39: =IF(M39>L39,"X","O") -> O | O39: - | P39: =IF(K39="X","l","") | Q39: =IF(N39="X","¡","") | Y39: =IF(N40="O",1,0) -> 1 | Z39: =IF(K40="O",1,0) -> 1
C40: Information security | D40: =D39+1 -> 31 | E40: Lead to incident | F40: 1/M | G40: Case | H40: 0 | I40: =SUMIFS(SDM_Data!$J$2:$J$1348,SDM_Data!$B$2:$B$1348,C40,SDM_Data!$D$2:$D$1348,E40,SDM_Data!$E$2:$E$1348,G40,SDM_Data!$I$2:$I$1348,$O$2) -> 0 | J40: =SUMIFS(SDM_Data!$K$2:$K$1348,SDM_Data!$B$2:$B$1348,C40,SDM_Data!$D$2:$D$1348,E40,SDM_Data!$E$2:$E$1348,G40,SDM_Data!$I$2:$I$1348,$O$2) -> 0 | K40: =IF(J40>I40,"X","O") -> O | L40: =SUMIFS(SDM_Data!$L$2:$L$1348,SDM_Data!$B$2:$B$1348,C40,SDM_Data!$D$2:$D$1348,E40,SDM_Data!$E$2:$E$1348,G40,SDM_Data!$I$2:$I$1348,$O$2) -> 0 | M40: =SUMIFS(SDM_Data!$M$2:$M$1348,SDM_Data!$B$2:$B$1348,C40,SDM_Data!$D$2:$D$1348,E40,SDM_Data!$E$2:$E$1348,G40,SDM_Data!$I$2:$I$1348,$O$2) -> 0 | N40: =IF(M40>L40,"X","O") -> O | O40: - | P40: =IF(K40="X","l","") | Q40: =IF(N40="X","¡","") | Y40: =IF(N41="O",1,0) -> 0 | Z40: =IF(K41="O",1,0) -> 1
C41: Information security | D41: =D40+1 -> 32 | E41: Nearmiss | F41: 1/M | G41: Case | H41: 0 | I41: =SUMIFS(SDM_Data!$J$2:$J$1348,SDM_Data!$B$2:$B$1348,C41,SDM_Data!$D$2:$D$1348,E41,SDM_Data!$E$2:$E$1348,G41,SDM_Data!$I$2:$I$1348,$O$2) -> 0 | J41: =SUMIFS(SDM_Data!$K$2:$K$1348,SDM_Data!$B$2:$B$1348,C41,SDM_Data!$D$2:$D$1348,E41,SDM_Data!$E$2:$E$1348,G41,SDM_Data!$I$2:$I$1348,$O$2) -> 0 | K41: =IF(J41>I41,"X","O") -> O | L41: =SUMIFS(SDM_Data!$L$2:$L$1348,SDM_Data!$B$2:$B$1348,C41,SDM_Data!$D$2:$D$1348,E41,SDM_Data!$E$2:$E$1348,G41,SDM_Data!$I$2:$I$1348,$O$2) -> 0 | M41: =SUMIFS(SDM_Data!$M$2:$M$1348,SDM_Data!$B$2:$B$1348,C41,SDM_Data!$D$2:$D$1348,E41,SDM_Data!$E$2:$E$1348,G41,SDM_Data!$I$2:$I$1348,$O$2) -> 5 | N41: =IF(M41>L41,"X","O") -> X | O41: - | P41: =IF(K41="X","l","") | Q41: =IF(N41="X","¡","") -> ¡ | R41: c | Y41: =IF(N42="O",1,0) -> 1 | Z41: =IF(K42="O",1,0) -> 1
...

Sheet Summary_SKD
B2: ="Overall Company KPI Achievement "&TEXT((TODAY()-29),"MMM-YY") -> Overall Company KPI Achievement Mar-26 | N2: 46054
B3: Company Measurement | F3: Frequency | G3: Unit | H3: FY25 Target | I3: Target | J3: Result | K3: Judge | L3: Accu. Target | M3: Accu. Result | N3: Accu. Judge | O3: Explain Item in PMM ●：Need ○：No Need | Q3: Key of problem | R3: Explain item/No. | T3: Overview result | Z3: Acc | AA3: Month
O4: Monthly | P4: Accu.
B5: 2. Quality | C5: Claim | D5: 1 | E5: Critical claim | F5: 1/M | G5: Case | H5: 0 | I5: =SUMIFS(SKD_data!$J$2:$J$584,Quality[Month],Summary_SKD!$N$2,Quality[measurment],Summary_SKD!E5,Quality[Unit],Summary_SKD!G5) -> 0 | J5: =SUMIFS(SKD_data!$K$2:$K$584,Quality[Month],Summary_SKD!$N$2,Quality[measurment],Summary_SKD!E5,Quality[Unit],Summary_SKD!G5) -> 0 | K5: =IF(J5>I5,"X","O") -> O | L5: =SUMIFS(SKD_data!$L$2:$L$584,Quality[Month],Summary_SKD!$N$2,Quality[measurment],Summary_SKD!E5,Quality[Unit],Summary_SKD!G5) -> 0 | M5: =SUMIFS(SKD_data!$M$2:$M$584,Quality[Month],Summary_SKD!$N$2,Quality[measurment],Summary_SKD!E5,Quality[Unit],Summary_SKD!G5) -> 0 | N5: =IF(M5>L5,"X","O") -> O | O5: =IF(K5="X","l","") | P5: =IF(N5="X","¡","") | Z5: =IF(N5="O",1,0) -> 1 | AA5: =IF(K5="O",1,0) -> 1
D6: 2 | E6: 0-km claim (Official) | F6: 1/M | G6: Case | H6: 1 | I6: =SUMIFS(SKD_data!$J$2:$J$584,Quality[Month],Summary_SKD!$N$2,Quality[measurment],Summary_SKD!E6,Quality[Unit],Summary_SKD!G6) -> 0 | J6: =SUMIFS(SKD_data!$K$2:$K$584,Quality[Month],Summary_SKD!$N$2,Quality[measurment],Summary_SKD!E6,Quality[Unit],Summary_SKD!G6) -> 0 | K6: =IF(J6>I6,"X","O") -> O | L6: =SUMIFS(SKD_data!$L$2:$L$584,Quality[Month],Summary_SKD!$N$2,Quality[measurment],Summary_SKD!E6,Quality[Unit],Summary_SKD!G6) -> 1 | M6: =SUMIFS(SKD_data!$M$2:$M$584,Quality[Month],Summary_SKD!$N$2,Quality[measurment],Summary_SKD!E6,Quality[Unit],Summary_SKD!G6) -> 0 | N6: =IF(M6>L6,"X","O") -> O | O6: =IF(K6="X","l","") | P6: =IF(N6="X","¡","") | T6: Monthly result | Z6: =IF(N6="O",1,0) -> 1 | AA6: =IF(K6="O",1,0) -> 1
D7: 3 | E7: 0-km claim (All DN response) | F7: 1/M | G7: Case | H7: 1 | I7: =SUMIFS(SKD_data!$J$2:$J$584,Quality[Month],Summary_SKD!$N$2,Quality[measurment],Summary_SKD!E7,Quality[Unit],Summary_SKD!G7) -> 0 | J7: =SUMIFS(SKD_data!$K$2:$K$584,Quality[Month],Summary_SKD!$N$2,Quality[measurment],Summary_SKD!E7,Quality[Unit],Summary_SKD!G7) -> 0 | K7: =IF(J7>I7,"X","O") -> O | L7: =SUMIFS(SKD_data!$L$2:$L$584,Quality[Month],Summary_SKD!$N$2,Quality[measurment],Summary_SKD!E7,Quality[Unit],Summary_SKD!G7) -> 1 | M7: =SUMIFS(SKD_data!$M$2:$M$584,Quality[Month],Summary_SKD!$N$2,Quality[measurment],Summary_SKD!E7,Quality[Unit],Summary_SKD!G7) -> 0 | N7: =IF(M7>L7,"X","O") -> O | O7: =IF(K7="X","l","") | P7: =IF(N7="X","¡","") | T7: Achieved | U7: Unachieved | V7: Total | Z7: =IF(N7="O",1,0) -> 1 | AA7: =IF(K7="O",1,0) -> 1
C8: Loss | D8: 4 | E8: Cost of spoilage | F8: 1/M | G8: % | H8: 0.0049 | I8: =SUMIFS(SKD_data!$J$2:$J$584,Quality[Month],Summary_SKD!$N$2,Quality[measurment],Summary_SKD!E8,Quality[Unit],Summary_SKD!G8) -> 0.0047233271 | J8: =SUMIFS(SKD_data!$K$2:$K$584,Quality[Month],Summary_SKD!$N$2,Quality[measurment],Summary_SKD!E8,Quality[Unit],Summary_SKD!G8) -> 0.00532 | K8: =IF(J8>I8,"X","O") -> X | L8: =SUMIFS(SKD_data!$L$2:$L$584,Quality[Month],Summary_SKD!$N$2,Quality[measurment],Summary_SKD!E8,Quality[Unit],Summary_SKD!G8) -> 0.0049055796 | M8: =SUMIFS(SKD_data!$M$2:$M$584,Quality[Month],Summary_SKD!$N$2,Quality[measurment],Summary_SKD!E8,Quality[Unit],Summary_SKD!G8) -> 0.00501 | N8: =IF(M8>L8,"X","O") -> X | O8: =IF(K8="X","l","") -> l | P8: =IF(N8="X","¡","") -> ¡ | Q8: 1.[One Times] SCV Kakou delay scrap NG (Keep Body Valve yellow stain for analysis root cause) 2.[Cont.] DF2 NG alarm over judge M/C - NG alarm sealing leak , part cap Fuel fiter NG No.0100 NG 1.8% | T8: =SUM(AA6:AA111) -> 12 | U8: =V8-T8 -> 7 | V8: =COUNT(AA6:AA111) -> 19
E9: Cost of spoilage | F9: 1/M | G9: MB | H9: 40.87MB | I9: =SUMIFS(SKD_data!$J$2:$J$584,Quality[Month],Summary_SKD!$N$2,Quality[measurment],Summary_SKD!E9,Quality[Unit],Summary_SKD!G9) -> 3.1303189 | J9: =SUMIFS(SKD_data!$K$2:$K$584,Quality[Month],Summary_SKD!$N$2,Quality[measurment],Summary_SKD!E9,Quality[Unit],Summary_SKD!G9) -> 3.8 | K9: =IF(J9>I9,"X","O") -> X | L9: =SUMIFS(SKD_data!$L$2:$L$584,Quality[Month],Summary_SKD!$N$2,Quality[measurment],Summary_SKD!E9,Quality[Unit],Summary_SKD!G9) -> 41.67 | M9: =SUMIFS(SKD_data!$M$2:$M$584,Quality[Month],Summary_SKD!$N$2,Quality[measurment],Summary_SKD!E9,Quality[Unit],Summary_SKD!G9) -> 41.2 | N9: =IF(M9>L9,"X","O") -> O | O9: =IF(K9="X","l","") -> l | P9: =IF(N9="X","¡","") | Z9: =IF(N9="O",1,0) -> 1 | AA9: =IF(K9="O",1,0) -> 0
B10: 4. Compliance | C10: Business compliance | E10: Urgent purchasing | F10: 1/M | G10: Case | H10: 73 | I10: =SUMIFS(SKD_data!$J$2:$J$584,Quality[Month],Summary_SKD!$N$2,Quality[measurment],Summary_SKD!E10,Quality[Unit],Summary_SKD!G10) -> 19 | J10: =SUMIFS(SKD_data!$K$2:$K$584,Quality[Month],Summary_SKD!$N$2,Quality[measurment],Summary_SKD!E10,Quality[Unit],Summary_SKD!G10) -> 8 | K10: =IF(J10>I10,"X","O") -> O | L10: =SUMIFS(SKD_data!$L$2:$L$584,Quality[Month],Summary_SKD!$N$2,Quality[measurment],Summary_SKD!E10,Quality[Unit],Summary_SKD!G10) -> 66 | M10: =SUMIFS(SKD_data!$M$2:$M$584,Quality[Month],Summary_SKD!$N$2,Quality[measurment],Summary_SKD!E10,Quality[Unit],Summary_SKD!G10) -> 41 | N10: =IF(M10>L10,"X","O") -> O | O10: =IF(K10="X","l","") | P10: =IF(N10="X","¡","") | T10: =T8/V8 -> 0.63157895
E11: Urgent purchasing | F11: 1/M | G11: MB | H11: 32.4 | I11: =SUMIFS(SKD_data!$J$2:$J$584,Quality[Month],Summary_SKD!$N$2,Quality[measurment],Summary_SKD!E11,Quality[Unit],Summary_SKD!G11) -> 13.639 | J11: =SUMIFS(SKD_data!$K$2:$K$584,Quality[Month],Summary_SKD!$N$2,Quality[measurment],Summary_SKD!E11,Quality[Unit],Summary_SKD!G11) -> 3.384 | K11: =IF(J11>I11,"X","O") -> O | L11: =SUMIFS(SKD_data!$L$2:$L$584,Quality[Month],Summary_SKD!$N$2,Quality[measurment],Summary_SKD!E11,Quality[Unit],Summary_SKD!G11) -> 30.95819 | M11: =SUMIFS(SKD_data!$M$2:$M$584,Quality[Month],Summary_SKD!$N$2,Quality[measurment],Summary_SKD!E11,Quality[Unit],Summary_SKD!G11) -> 10.865638 | N11: =IF(M11>L11,"X","O") -> O | O11: =IF(K11="X","l","") | P11: =IF(N11="X","¡","") | Z11: =IF(N11="O",1,0) -> 1 | AA11: =IF(K11="O",1,0) -> 1
E12: Urgent purchasing clear within3 Month | F12: 1/M | G12: Case | H12: 0 | I12: =SUMIFS(SKD_data!$J$2:$J$584,Quality[Month],Summary_SKD!$N$2,Quality[measurment],Summary_SKD!E12,Quality[Unit],Summary_SKD!G12) -> 0 | J12: =SUMIFS(SKD_data!$K$2:$K$584,Quality[Month],Summary_SKD!$N$2,Quality[measurment],Summary_SKD!E12,Quality[Unit],Summary_SKD!G12) -> 0 | K12: =IF(J12>I12,"X","O") -> O | L12: =SUMIFS(SKD_data!$L$2:$L$584,Quality[Month],Summary_SKD!$N$2,Quality[measurment],Summary_SKD!E12,Quality[Unit],Summary_SKD!G12) -> 0 | M12: =SUMIFS(SKD_data!$M$2:$M$584,Quality[Month],Summary_SKD!$N$2,Quality[measurment],Summary_SKD!E12,Quality[Unit],Summary_SKD!G12) -> 0 | N12: =IF(M12>L12,"X","O") -> O | O12: =IF(K12="X","l","") | P12: =IF(N12="X","¡","") | T12: Accumulate result
E13: Urgent purchasing clear within3 Month | F13: 1/M | G13: MB | H13: 0 | I13: =SUMIFS(SKD_data!$J$2:$J$584,Quality[Month],Summary_SKD!$N$2,Quality[measurment],Summary_SKD!E13,Quality[Unit],Summary_SKD!G13) -> 0 | J13: =SUMIFS(SKD_data!$K$2:$K$584,Quality[Month],Summary_SKD!$N$2,Quality[measurment],Summary_SKD!E13,Quality[Unit],Summary_SKD!G13) -> 0 | K13: =IF(J13>I13,"X","O") -> O | L13: =SUMIFS(SKD_data!$L$2:$L$584,Quality[Month],Summary_SKD!$N$2,Quality[measurment],Summary_SKD!E13,Quality[Unit],Summary_SKD!G13) -> 0 | M13: =SUMIFS(SKD_data!$M$2:$M$584,Quality[Month],Summary_SKD!$N$2,Quality[measurment],Summary_SKD!E13,Quality[Unit],Summary_SKD!G13) -> 0 | N13: =IF(M13>L13,"X","O") -> O | O13: =IF(K13="X","l","") | P13: =IF(N13="X","¡","") | T13: Achieved | U13: Unachieved | V13: Total | Z13: =IF(N13="O",1,0) -> 1 | AA13: =IF(K13="O",1,0) -> 1
E14: Special purchasing | F14: 1/M | G14: Case | H14: 43 | I14: =SUMIFS(SKD_data!$J$2:$J$584,Quality[Month],Summary_SKD!$N$2,Quality[measurment],Summary_SKD!E14,Quality[Unit],Summary_SKD!G14) -> 10 | J14: =SUMIFS(SKD_data!$K$2:$K$584,Quality[Month],Summary_SKD!$N$2,Quality[measurment],Summary_SKD!E14,Quality[Unit],Summary_SKD!G14) -> 4 | K14: =IF(J14>I14,"X","O") -> O | L14: =SUMIFS(SKD_data!$L$2:$L$584,Quality[Month],Summary_SKD!$N$2,Quality[measurment],Summary_SKD!E14,Quality[Unit],Summary_SKD!G14) -> 40 | M14: =SUMIFS(SKD_data!$M$2:$M$584,Quality[Month],Summary_SKD!$N$2,Quality[measurment],Summary_SKD!E14,Quality[Unit],Summary_SKD!G14) -> 38 | N14: =IF(M14>L14,"X","O") -> O | O14: =IF(K14="X","l","") | P14: =IF(N14="X","¡","") | T14: =SUM(Z6:Z111) -> 15 | U14: =V14-T14 -> 8 | V14: =COUNT(Z6:Z111) -> 23
E15: Special purchasing | F15: 1/M | G15: MB | H15: 78.7 | I15: =SUMIFS(SKD_data!$J$2:$J$584,Quality[Month],Summary_SKD!$N$2,Quality[measurment],Summary_SKD!E15,Quality[Unit],Summary_SKD!G15) -> 14.1 | J15: =SUMIFS(SKD_data!$K$2:$K$584,Quality[Month],Summary_SKD!$N$2,Quality[measurment],Summary_SKD!E15,Quality[Unit],Summary_SKD!G15) -> 1.048 | K15: =IF(J15>I15,"X","O") -> O | L15: =SUMIFS(SKD_data!$L$2:$L$584,Quality[Month],Summary_SKD!$N$2,Quality[measurment],Summary_SKD!E15,Quality[Unit],Summary_SKD!G15) -> 71 | M15: =SUMIFS(SKD_data!$M$2:$M$584,Quality[Month],Summary_SKD!$N$2,Quality[measurment],Summary_SKD!E15,Quality[Unit],Summary_SKD!G15) -> 43.678 | N15: =IF(M15>L15,"X","O") -> O | O15: =IF(K15="X","l","") | P15: =IF(N15="X","¡","") | Z15: =IF(N15="O",1,0) -> 1 | AA15: =IF(K15="O",1,0) -> 1
C16: Asset control | D16: 5 | E16: Idle Fixed Assets | F16: 1/M | G16: Case | H16: - | I16: - | J16: - | K16: - | L16: =SUMIFS(SKD_data!$L$2:$L$584,Quality[Month],Summary_SKD!$N$2,Quality[measurment],Summary_SKD!E16,Quality[Unit],Summary_SKD!G16) -> 0 | M16: =SUMIFS(SKD_data!$M$2:$M$584,Quality[Month],Summary_SKD!$N$2,Quality[measurment],Summary_SKD!E16,Quality[Unit],Summary_SKD!G16) -> 0 | N16: =IF(M16>L16,"X","O") -> O | O16: =IF(K16="X","l","") | P16: =IF(N16="X","¡","") | T16: =T14/V14 -> 0.65217391
E17: Idle Fixed Assets | F17: 1/M | G17: MB | H17: - | I17: - | J17: - | K17: - | L17: =SUMIFS(SKD_data!$L$2:$L$584,Quality[Month],Summary_SKD!$N$2,Quality[measurment],Summary_SKD!E17,Quality[Unit],Summary_SKD!G17) -> 0 | M17: =SUMIFS(SKD_data!$M$2:$M$584,Quality[Month],Summary_SKD!$N$2,Quality[measurment],Summary_SKD!E17,Quality[Unit],Summary_SKD!G17) -> 0 | N17: =IF(M17>L17,"X","O") -> O | O17: =IF(K17="X","l","") | P17: =IF(N17="X","¡","")
D18: 6 | E18: CIP (No using date) | F18: 1/M | G18: Case | H18: - | I18: - | J18: - | K18: - | L18: - | M18: =SUMIFS(SKD_data!$M$2:$M$584,Quality[Month],Summary_SKD!$N$2,Quality[measurment],Summary_SKD!E18,Quality[Unit],Summary_SKD!G18) -> 28 | N18: - | O18: =IF(K18="X","l","") | P18: =IF(N18="X","¡","") | Q18: CIP (No using date) No record INV on system PE : 12 case, 6.86 MB. PU : 12 case, 18.49 MB. PD : 3 case, 3.57 MB. MT : 1 case, 0.04 MB.
E19: CIP (No using date) | F19: 1/M | G19: MB | H19: - | I19: - | J19: - | K19: - | L19: - | M19: =SUMIFS(SKD_data!$M$2:$M$584,Quality[Month],Summary_SKD!$N$2,Quality[measurment],Summary_SKD!E19,Quality[Unit],Summary_SKD!G19) -> 32.49 | N19: - | O19: =IF(K19="X","l","") | P19: =IF(N19="X","¡","")
D20: 7 | E20: CIP (Document not complete) | F20: 1/M | G20: Case | H20: - | I20: - | J20: - | K20: - | L20: - | M20: =SUMIFS(SKD_data!$M$2:$M$584,Quality[Month],Summary_SKD!$N$2,Quality[measurment],Summary_SKD!E20,Quality[Unit],Summary_SKD!G20) -> 19 | N20: - | O20: =IF(K20="X","l","") | P20: =IF(N20="X","¡","") | Q20: CIP (Document not complete) Under process approval & No submit analysis PE : 7 case, 4.6 MB. PU : 3 case, 2.09 MB. PD : 9 case, 8.01 MB.
E21: CIP (Document not complete) | F21: 1/M | G21: MB | H21: - | I21: - | J21: - | K21: - | L21: - | M21: =SUMIFS(SKD_data!$M$2:$M$584,Quality[Month],Summary_SKD!$N$2,Quality[measurment],Summary_SKD!E21,Quality[Unit],Summary_SKD!G21) -> 35.96 | N21: - | O21: =IF(K21="X","l","") | P21: =IF(N21="X","¡","")
D22: 8 | E22: CIP > 12 Month | F22: 1/M | G22: Case | H22: 0 | I22: =SUMIFS(SKD_data!$J$2:$J$584,Quality[Month],Summary_SKD!$N$2,Quality[measurment],Summary_SKD!E22,Quality[Unit],Summary_SKD!G22) -> 3 | J22: =SUMIFS(SKD_data!$K$2:$K$584,Quality[Month],Summary_SKD!$N$2,Quality[measurment],Summary_SKD!E22,Quality[Unit],Summary_SKD!G22) -> 0 | K22: =IF(J22>=I22,"O","X") -> X | L22: =SUMIFS(SKD_data!$L$2:$L$584,Quality[Month],Summary_SKD!$N$2,Quality[measurment],Summary_SKD!E22,Quality[Unit],Summary_SKD!G22) -> 3 | M22: =SUMIFS(SKD_data!$M$2:$M$584,Quality[Month],Summary_SKD!$N$2,Quality[measurment],Summary_SKD!E22,Quality[Unit],Summary_SKD!G22) -> 4 | N22: =IF(M22<L22,"O","X") -> X | O22: =IF(K22="X","¡","") -> ¡ | P22: =IF(N22="X","¡","") -> ¡ | Q22: (CIP >12 M) Complete 2 item 1.7MB trf in Jan.26 Over revise plan : PE : 1 Case 0.94MB (Waiting memo for cancel PO and record to expense) Transfer in FY26 PE : 1case 1.7MB (WASHING SOL 1W (G2G3) MC1 & MC2) | R22: Report in TMM 31/Mar By ACC/PE GM | Z22: =IF(N22="O",1,0) -> 0 | AA22: =IF(K22="O",1,0) -> 0
E23: CIP > 12 Month | F23: 1/M | G23: MB | H23: 0 | I23: =SUMIFS(SKD_data!$J$2:$J$584,Quality[Month],Summary_SKD!$N$2,Quality[measurment],Summary_SKD!E23,Quality[Unit],Summary_SKD!G23) -> 2.64 | J23: =SUMIFS(SKD_data!$K$2:$K$584,Quality[Month],Summary_SKD!$N$2,Quality[measurment],Summary_SKD!E23,Quality[Unit],Summary_SKD!G23) -> 0 | K23: =IF(J23>=I23,"O","X") -> X | L23: =SUMIFS(SKD_data!$L$2:$L$584,Quality[Month],Summary_SKD!$N$2,Quality[measurment],Summary_SKD!E23,Quality[Unit],Summary_SKD!G23) -> 3.5 | M23: =SUMIFS(SKD_data!$M$2:$M$584,Quality[Month],Summary_SKD!$N$2,Quality[measurment],Summary_SKD!E23,Quality[Unit],Summary_SKD!G23) -> 4.5 | N23: =IF(M23<L23,"O","X") -> X | O23: =IF(K23="X","¡","") -> ¡ | P23: =IF(N23="X","¡","") -> ¡
D24: 9 | E24: CIP > 18 Month | F24: 1/M | G24: Case | H24: 0 | I24: =SUMIFS(SKD_data!$J$2:$J$584,Quality[Month],Summary_SKD!$N$2,Quality[measurment],Summary_SKD!E24,Quality[Unit],Summary_SKD!G24) -> 2 | J24: =SUMIFS(SKD_data!$K$2:$K$584,Quality[Month],Summary_SKD!$N$2,Quality[measurment],Summary_SKD!E24,Quality[Unit],Summary_SKD!G24) -> 1 | K24: =IF(J24>=I24,"O","X") -> X | L24: =SUMIFS(SKD_data!$L$2:$L$584,Quality[Month],Summary_SKD!$N$2,Quality[measurment],Summary_SKD!E24,Quality[Unit],Summary_SKD!G24) -> 1 | M24: =SUMIFS(SKD_data!$M$2:$M$584,Quality[Month],Summary_SKD!$N$2,Quality[measurment],Summary_SKD!E24,Quality[Unit],Summary_SKD!G24) -> 3 | N24: =IF(M24<L24,"O","X") -> X | O24: =IF(K24="X","¡","") -> ¡ | P24: =IF(N24="X","¡","") -> ¡ | R24: Report in TMM 31/Mar By ACC/PE GM | Z24: =IF(N24="O",1,0) -> 0 | AA24: =IF(K24="O",1,0) -> 0
E25: CIP > 18 Month | F25: 1/M | G25: MB | H25: 0 | I25: =SUMIFS(SKD_data!$J$2:$J$584,Quality[Month],Summary_SKD!$N$2,Quality[measurment],Summary_SKD!E25,Quality[Unit],Summary_SKD!G25) -> 1.76 | J25: =SUMIFS(SKD_data!$K$2:$K$584,Quality[Month],Summary_SKD!$N$2,Quality[measurment],Summary_SKD!E25,Quality[Unit],Summary_SKD!G25) -> 1.06 | K25: =IF(J25>=I25,"O","X") -> X | L25: =SUMIFS(SKD_data!$L$2:$L$584,Quality[Month],Summary_SKD!$N$2,Quality[measurment],Summary_SKD!E25,Quality[Unit],Summary_SKD!G25) -> 1.55 | M25: =SUMIFS(SKD_data!$M$2:$M$584,Quality[Month],Summary_SKD!$N$2,Quality[measurment],Summary_SKD!E25,Quality[Unit],Summary_SKD!G25) -> 1.76 | N25: =IF(M25<L25,"O","X") -> X | O25: =IF(K25="X","¡","") -> ¡ | P25: =IF(N25="X","¡","") -> ¡
D26: 10 | E26: Un-received Order >12 [expense] | F26: 1/M | G26: Case | H26: - | I26: - | J26: - | K26: - | L26: =SUMIFS(SKD_data!$L$2:$L$584,Quality[Month],Summary_SKD!$N$2,Quality[measurment],Summary_SKD!E26,Quality[Unit],Summary_SKD!G26) -> 0 | M26: =SUMIFS(SKD_data!$M$2:$M$584,Quality[Month],Summary_SKD!$N$2,Quality[measurment],Summary_SKD!E26,Quality[Unit],Summary_SKD!G26) -> 13 | N26: =IF(M26>L26,"X","O") -> X | O26: =IF(K26="X","l","") | P26: =IF(N26="X","¡","") -> ¡ | Q26: SKD expense : PD common : 6 cases = 1.60 MB PUR common : 2 cases = 1.79 MB **Data date of 10 Mar'26** | R26: Report in TMM 24-Feb Report by Pruek /GM
E27: Un-received Order >12 [expense] | F27: 1/M | G27: MB | H27: - | I27: - | J27: - | K27: - | L27: =SUMIFS(SKD_data!$L$2:$L$584,Quality[Month],Summary_SKD!$N$2,Quality[measurment],Summary_SKD!E27,Quality[Unit],Summary_SKD!G27) -> 0 | M27: =SUMIFS(SKD_data!$M$2:$M$584,Quality[Month],Summary_SKD!$N$2,Quality[measurment],Summary_SKD!E27,Quality[Unit],Summary_SKD!G27) -> 3.548 | N27: =IF(M27>L27,"X","O") -> X | O27: =IF(K27="X","l","") | P27: =IF(N27="X","¡","") -> ¡ | R27: Report in TMM 10-Mar By each Dept. | Z27: =IF(N27="O",1,0) -> 0 | AA27: =IF(K27="O",1,0) -> 0
D28: 11 | E28: Un-received Order >18 [Investment] | F28: 1/M | G28: Case | H28: - | I28: - | J28: - | K28: - | L28: =SUMIFS(SKD_data!$L$2:$L$584,Quality[Month],Summary_SKD!$N$2,Quality[measurment],Summary_SKD!E28,Quality[Unit],Summary_SKD!G28) -> 0 | M28: =SUMIFS(SKD_data!$M$2:$M$584,Quality[Month],Summary_SKD!$N$2,Quality[measurment],Summary_SKD!E28,Quality[Unit],Summary_SKD!G28) -> 37 | N28: =IF(M28>L28,"X","O") -> X | O28: =IF(K28="X","l","") | P28: =IF(N28="X","¡","") -> ¡ | Q28: SKD Investment PU common : 18 cases = 25.44 MB PD (Fuel filter) : 7 cases = 0.744 MB PD (Valve) 4 cases = 1.57 MB **Data date of 10 Mar'26** | R28: Report in TMM 24-Feb Report by Pruek /GM
E29: Un-received Order >18 [Investment] | F29: 1/M | G29: MB | H29: - | I29: - | J29: - | K29: - | L29: =SUMIFS(SKD_data!$L$2:$L$584,Quality[Month],Summary_SKD!$N$2,Quality[measurment],Summary_SKD!E29,Quality[Unit],Summary_SKD!G29) -> 0 | M29: =SUMIFS(SKD_data!$M$2:$M$584,Quality[Month],Summary_SKD!$N$2,Quality[measurment],Summary_SKD!E29,Quality[Unit],Summary_SKD!G29) -> 37.111 | N29: =IF(M29>L29,"X","O") -> X | O29: =IF(K29="X","l","") | P29: =IF(N29="X","¡","") -> ¡ | R29: Report in TMM 10-Mar By each Dept. | Z29: =IF(N29="O",1,0) -> 0 | AA29: =IF(K29="O",1,0) -> 0
D30: 12 | E30: Inventory variance | F30: 1/6M | G30: % | H30: - | I30: - | J30: - | K30: - | L30: =SUMIFS(SKD_data!$L$2:$L$584,Quality[Month],Summary_SKD!$N$2,Quality[measurment],Summary_SKD!E30,Quality[Unit],Summary_SKD!G30) -> -0.005 | M30: =SUMIFS(SKD_data!$M$2:$M$584,Quality[Month],Summary_SKD!$N$2,Quality[measurment],Summary_SKD!E30,Quality[Unit],Summary_SKD!G30) -> -0.004 | N30: =IF(M30<L30,"X","O") -> O | O30: =IF(K30="X","l","") | P30: =IF(N30="X","¡","") | Z30: =IF(N30="O",1,0) -> 1 | AA30: =IF(K30="O",1,0) -> 0
E31: Inventory variance | F31: 1/6M | G31: MB | H31: - | I31: - | J31: - | K31: - | L31: =SUMIFS(SKD_data!$L$2:$L$584,Quality[Month],Summary_SKD!$N$2,Quality[measurment],Summary_SKD!E31,Quality[Unit],Summary_SKD!G31) -> 0 | M31: =SUMIFS(SKD_data!$M$2:$M$584,Quality[Month],Summary_SKD!$N$2,Quality[measurment],Summary_SKD!E31,Quality[Unit],Summary_SKD!G31) -> -2.12 | N31: =IF(M31>L31,"X","O") -> O | O31: =IF(K31="X","l","") | P31: =IF(N31="X","¡","")
D32: 13 | E32: Spare part inventory | F32: 1/6M | G32: % | H32: 0.0342 | I32: =SUMIFS(SKD_data!$J$2:$J$584,Quality[Month],Summary_SKD!$N$2,Quality[measurment],Summary_SKD!E32,Quality[Unit],Summary_SKD!G32) -> 0.0298 | J32: =SUMIFS(SKD_data!$K$2:$K$584,Quality[Month],Summary_SKD!$N$2,Quality[measurment],Summary_SKD!E32,Quality[Unit],Summary_SKD!G32) -> 0.0276 | K32: =IF(J32>I32,"X","O") -> O | L32: =SUMIFS(SKD_data!$L$2:$L$584,Quality[Month],Summary_SKD!$N$2,Quality[measurment],Summary_SKD!E32,Quality[Unit],Summary_SKD!G32) -> 0.0298 | M32: =SUMIFS(SKD_data!$M$2:$M$584,Quality[Month],Summary_SKD!$N$2,Quality[measurment],Summary_SKD!E32,Quality[Unit],Summary_SKD!G32) -> 0.0276 | N32: =IF(M32>L32,"X","O") -> O | O32: =IF(K32="X","l","") | P32: =IF(N32="X","¡","") | Z32: =IF(N32="O",1,0) -> 1 | AA32: =IF(K32="O",1,0) -> 1
E33: Spare part inventory | F33: 1/6M | G33: MB | H33: - | I33: =SUMIFS(SKD_data!$J$2:$J$584,Quality[Month],Summary_SKD!$N$2,Quality[measurment],Summary_SKD!E33,Quality[Unit],Summary_SKD!G33) -> 104.35 | J33: =SUMIFS(SKD_data!$K$2:$K$584,Quality[Month],Summary_SKD!$N$2,Quality[measurment],Summary_SKD!E33,Quality[Unit],Summary_SKD!G33) -> 96.09 | K33: =IF(J33>I33,"X","O") -> O | L33: =SUMIFS(SKD_data!$L$2:$L$584,Quality[Month],Summary_SKD!$N$2,Quality[measurment],Summary_SKD!E33,Quality[Unit],Summary_SKD!G33) -> 104.35 | M33: =SUMIFS(SKD_data!$M$2:$M$584,Quality[Month],Summary_SKD!$N$2,Quality[measurment],Summary_SKD!E33,Quality[Unit],Summary_SKD!G33) -> 96.09 | N33: =IF(M33>L33,"X","O") -> O | O33: =IF(K33="X","l","") | P33: =IF(N33="X","¡","")
D34: 14 | E34: Slow moving of FG | F34: 1/3M | G34: MB | H34: 3.17 | I34: - | J34: =SUMIFS(SKD_data!$K$2:$K$584,Quality[Month],Summary_SKD!$N$2,Quality[measurment],Summary_SKD!E34,Quality[Unit],Summary_SKD!G34) -> 0 | K34: - | L34: =SUMIFS(SKD_data!$L$2:$L$584,Quality[Month],Summary_SKD!$N$2,Quality[measurment],Summary_SKD!E34,Quality[Unit],Summary_SKD!G34) -> 0.12 | M34: =SUMIFS(SKD_data!$M$2:$M$584,Quality[Month],Summary_SKD!$N$2,Quality[measurment],Summary_SKD!E34,Quality[Unit],Summary_SKD!G34) -> 0.4 | N34: =IF(M34>L34,"X","O") -> X | O34: =IF(K34="X","l","") | P34: =IF(N34="X","¡","") -> ¡ | R34: Resul of Dec'25 | Z34: =IF(N34="O",1,0) -> 0
D35: 15 | E35: Slow moving of Parts&RM | F35: 1/3M | G35: MB | H35: - | I35: - | J35: - | K35: - | L35: =SUMIFS(SKD_data!$L$2:$L$584,Quality[Month],Summary_SKD!$N$2,Quality[measurment],Summary_SKD!E35,Quality[Unit],Summary_SKD!G35) -> 2 | M35: =SUMIFS(SKD_data!$M$2:$M$584,Quality[Month],Summary_SKD!$N$2,Quality[measurment],Summary_SKD!E35,Quality[Unit],Summary_SKD!G35) -> 0.9 | N35: =IF(M35>L35,"X","O") -> O | O35: =IF(K35="X","l","") | P35: =IF(N35="X","¡","") | Z35: =IF(N35="O",1,0) -> 1
D36: 16 | E36: Slow moving of Spare Parts | F36: 1/3M | G36: MB | H36: - | I36: - | J36: - | K36: - | L36: =SUMIFS(SKD_data!$L$2:$L$584,Quality[Month],Summary_SKD!$N$2,Quality[measurment],Summary_SKD!E36,Quality[Unit],Summary_SKD!G36) -> 30.2 | M36: =SUMIFS(SKD_data!$M$2:$M$584,Quality[Month],Summary_SKD!$N$2,Quality[measurment],Summary_SKD!E36,Quality[Unit],Summary_SKD!G36) -> 31.9 | N36: =IF(M36>L36,"X","O") -> X | O36: =IF(K36="X","l","") | P36: =IF(N36="X","¡","") -> ¡ | R36: Result of Dec'25 | Z36: =IF(N36="O",1,0) -> 0 | AA36: =IF(K36="O",1,0) -> 0
D37: 17 | E37: Dead stock of FG, PART & RM | F37: 1/Y | G37: MB | H37: 5.4 | I37: - | J37: =SUMIFS(SKD_data!$K$2:$K$584,Quality[Month],Summary_SKD!$N$2,Quality[measurment],Summary_SKD!E37,Quality[Unit],Summary_SKD!G37) -> 0 | K37: - | L37: =SUMIFS(SKD_data!$L$2:$L$584,Quality[Month],Summary_SKD!$N$2,Quality[measurment],Summary_SKD!E37,Quality[Unit],Summary_SKD!G37) -> 0 | M37: =SUMIFS(SKD_data!$M$2:$M$584,Quality[Month],Summary_SKD!$N$2,Quality[measurment],Summary_SKD!E37,Quality[Unit],Summary_SKD!G37) -> 0 | N37: - | O37: =IF(K37="X","l","") | P37: =IF(N37="X","¡","")
D38: 18 | E38: Dead stock of Spare parts | F38: 1/Y | G38: MB | H38: 3 | I38: - | J38: =SUMIFS(SKD_data!$K$2:$K$584,Quality[Month],Summary_SKD!$N$2,Quality[measurment],Summary_SKD!E38,Quality[Unit],Summary_SKD!G38) -> 0 | K38: - | L38: =SUMIFS(SKD_data!$L$2:$L$584,Quality[Month],Summary_SKD!$N$2,Quality[measurment],Summary_SKD!E38,Quality[Unit],Summary_SKD!G38) -> 0 | M38: =SUMIFS(SKD_data!$M$2:$M$584,Quality[Month],Summary_SKD!$N$2,Quality[measurment],Summary_SKD!E38,Quality[Unit],Summary_SKD!G38) -> 0 | N38: - | O38: =IF(K38="X","l","") | P38: =IF(N38="X","¡","")
B39: 8. Cost | C39: Sale | D39: 19 | E39: Sale | F39: 1/M | G39: MB | H39: 8293.83 | I39: =SUMIFS(SKD_data!$J$2:$J$584,Quality[Month],Summary_SKD!$N$2,Quality[measurment],Summary_SKD!E39,Quality[Unit],Summary_SKD!G39,Quality[[Sub ]],Summary_SKD!C39) -> 654.38259 | J39: =SUMIFS(SKD_data!$K$2:$K$584,Quality[Month],Summary_SKD!$N$2,Quality[measurment],Summary_SKD!E39,Quality[Unit],Summary_SKD!G39,Quality[[Sub ]],Summary_SKD!C39) -> 711 | K39: =IF(J39<I39,"X","O") -> O | L39: =SUMIFS(SKD_data!$L$2:$L$584,Quality[Month],Summary_SKD!$N$2,Quality[measurment],Summary_SKD!E39,Quality[Unit],Summary_SKD!G39,Quality[[Sub ]],Summary_SKD!C39) -> 7606.5082 | M39: =SUMIFS(SKD_data!$M$2:$M$584,Quality[Month],Summary_SKD!$N$2,Quality[measurment],Summary_SKD!E39,Quality[Unit],Summary_SKD!G39,Quality[[Sub ]],Summary_SKD!C39) -> 8076.2591 | N39: =IF(M39<L39,"X","O") -> O | O39: =IF(K39="X","l","") | P39: =IF(N39="X","¡","") | Z39: =IF(N39="O",1,0) -> 1 | AA39: =IF(K39="O",1,0) -> 1
C40: Profit | D40: 20 | E40: Amount | F40: 1/M | G40: MB | H40: 675.95 | I40: =SUMIFS(SKD_data!$J$2:$J$584,Quality[Month],Summary_SKD!$N$2,Quality[measurment],Summary_SKD!E40,Quality[Unit],Summary_SKD!G40,Quality[[Sub ]],Summary_SKD!C40) -> 61.201754 | J40: =SUMIFS(SKD_data!$K$2:$K$584,Quality[Month],Summary_SKD!$N$2,Quality[measurment],Summary_SKD!E40,Quality[Unit],Summary_SKD!G40,Quality[[Sub ]],Summary_SKD!C40) -> 66 | K40: =IF(J40>I40,"O","X") -> O | L40: =SUMIFS(SKD_data!$L$2:$L$584,Quality[Month],Summary_SKD!$N$2,Quality[measurment],Summary_SKD!E40,Quality[Unit],Summary_SKD!G40,Quality[[Sub ]],Summary_SKD!C40) -> 616.34532 | M40: =SUMIFS(SKD_data!$M$2:$M$584,Quality[Month],Summary_SKD!$N$2,Quality[measurment],Summary_SKD!E40,Quality[Unit],Summary_SKD!G40,Quality[[Sub ]],Summary_SKD!C40) -> 935.30399 | N40: =IF(M40>L40,"O","X") -> O | O40: =IF(K40="X","l","") | P40: =IF(N40="X","¡","") | Z40: =IF(N40="O",1,0) -> 1 | AA40: =IF(K40="O",1,0) -> 1
